Workbook

Sheet 说明与口径
A1: 宇树科技经营与财务分析底稿——编制说明与口径
A2: 项目 | B2: 内容
A3: 分析对象 | B3: 宇树科技股份有限公司（证券代码：688836.SH，证券简称：宇树科技-W），高性能通用人形机器人、四足机器人、机器人组件及具身智能模型的研发、生产和销售。
A4: 资料截止时间 | B4: 2026年8月30日（上市后二级市场数据仅采用截至该日的公开信息）。
A5: 编制时间 | B5: 2026年9月4日。
A6: 金额单位 | B6: 人民币万元（另标注除外；图表中为亿元）。百分比均以百分数列示。
A7: 报告期口径 | B7: 年度：2022/2023/2024/2025年度；期间：2025H1（上半年）、2025Q1-3（前三季度）、2026Q1（一季度）、2026H1（上半年）。同比比较一律采用相同报告期口径（如2026H1对2025H1）。
A8: 资料优先级 | B8: A级：上交所披露文件（招股说明书申报稿、科创板上市公告书、定期报告）；B级：公司官方公开资料（官网等）；C级：权威财经媒体报道（证券时报、21世纪经济报道、中新经纬、中国经济网等，用于交叉验证）；D级：据披露增速反推的推算值（均已在表中标注）。
A9: 数据性质标注 | B9: 原始数据表中每行均标注数据性质；推算值、约数均写入备注，未将任何预测数据当作已发生事实（机构预测单独存放于“预测参考(非事实)”表）。
A10: 重要口径差异提示1 | B10: 2025年度营业收入：招股说明书申报稿（2026-03-20受理稿）披露为17.08亿元；科创板上市公告书/年报口径为16.99亿元（169,926.93万元）。本底稿以16.99亿元（上市公告书/年报口径）为准，差异原因待核对原文。
A11: 重要口径差异提示2 | B11: 毛利率存在“主营业务毛利率”（招股书口径）与“销售毛利率”（整体报表口径）两套数据，且招股书不同版本（申报稿/上会稿）数字略有差异，本底稿分两行分别列示并在备注中说明。
A12: 重要口径差异提示3 | B12: 2025年归母净利润约2.78亿元、净利润（含少数股东）约2.88亿元，媒体转引存在2.78/2.88亿元两种表述，疑为归母与含少数股东口径之别，精确值需以2025年年度报告为准。
A13: 编辑说明 | B13: 本工作簿为可编辑底稿：黄色浅底区域为计算区（含公式，请勿直接覆盖）；修改原始数据后，核心计算与图表数据将联动更新。
A14: 免责声明 | B14: 本底稿基于公开信息整理，仅供研究参考，不构成投资建议。所引媒体与券商数据未经审计，使用前请按“待人工核验清单”逐项核对交易所披露原文。
A16: 待人工核验清单（使用前请逐项核对披露原文）
A17: 1. 2025年度归母净利润精确值（媒体口径2.78亿/2.88亿元并存，需以2025年年报利润表为准）。
A18: 2. 2025年度营收申报稿17.08亿元与年报16.99亿元差异原因（是否审计调整），需核对年报原文。
A19: 3. 2024年研发费用精确值：本文按“研发费用率17.8%×营收”推算约6,983万元，需以年报为准。
A20: 4. 2022年扣非归母净利润-807万元为媒体转引招股书数据，精确到元的数值待核。
A21: 5. 各期毛利率“主营/整体”口径及申报稿与上会稿版本差异，需对照招股书原文核对。
A22: 6. 经营活动现金流净额为约数（2025年“超6.7亿元”、2024年约1.9亿元为按“增加4.8亿元”反推），需以现金流量表为准。
A23: 7. 2025H1营收77,560万元、扣非30,250万元系按2026H1披露同比增速反推，需与2025年半年度报告核对。
A24: 8. 历史收入结构占比（人形1.88%/27.6%等）的分母为主营业务收入口径，需核对招股书分部数据表。
A25: 9. 资产总额/流动资产2025年末数为按2026H1披露增幅反推，需与2025年报资产负债表核对。
A26: 10. 券商盈利预测（野村、招商证券）来自媒体转引，未经研报原文核验，仅供方向性参考。

Sheet 资料来源
A1: 资料来源清单（按优先级排序，资料截止2026-08-30）
A2: 序号 | B2: 资料名称 | C2: 资料类型 | D2: 披露/发布方 | E2: 披露/发布日期 | F2: 涉及报告期 | G2: 主要引用数据 | H2: 链接 | I2: 备注
A3: 1 | B3: 宇树科技首次公开发行股票并在科创板上市招股说明书（申报稿） | C3: 交易所披露文件（A级） | D3: 上海证券交易所/宇树科技 | E3: 2026-03-20（受理日披露） | F3: 2022-2025年度、2025Q1-3 | G3: 营收、归母净利、扣非净利、主营业务毛利率、收入结构、销量、募投计划、2026H1业绩预告 | H3: www.sse.com.cn（发行上市审核项目页面） | I3: IPO受理稿，申报口径财务数据
A4: 2 | B4: 首次公开发行股票科创板上市公告书（含2026年上半年业绩更新） | C4: 交易所披露文件（A级） | D4: 上海证券交易所/宇树科技 | E4: 2026-08-17 | F4: 2026H1、2025H1（对比数）、2025年度 | G4: 2026H1营收11.52亿元/归母2.74亿元/扣非2.44亿元、总资产38.45亿元、增速与费用变动说明 | H4: www.sse.com.cn | I4: 2026-08-19上市前披露，上市后首份经审阅半年数据
A5: 3 | B5: 宇树科技2025年年度报告（688836） | C5: 定期报告（A级） | D5: 宇树科技 | E5: 2026年上半年披露 | F5: 2025年度 | G5: 2025年度收入构成（产品/地域）、研发费用14,496.56万元、销售毛利率60.44%、净利润数据 | H5: www.sse.com.cn | I5: A股财务数据库转引年报数据，建议核对年报原文
A6: 4 | B6: 宇树科技2026年第一季度报告（688836） | C6: 定期报告（A级） | D6: 宇树科技 | E6: 2026年4月 | F6: 2026Q1、2025Q1 | G6: 2026Q1营收42,284.05万元（+68.49%）、扣非4,025.36万元（-52.55%）、毛利率58.42%、研发费用6,319.31万元 | H6: www.sse.com.cn | I6: 媒体及行情数据库转引，建议核对原文
A7: 5 | B7: 宇树科技官方网站及官方公开信息 | C7: 官方公开资料（B级） | D7: 宇树科技 | E7: 持续更新 | F7: —— | G7: 公司业务描述、产品矩阵（H1/G1/G2/H2/B2/Go2等）、组织与招聘信息 | H7: www.unitree.com | I7: 非财务数据来源
A8: 6 | B8: 证券时报、21世纪经济报道、中新经纬、中国经济网、广州日报等报道 | C8: 权威财经媒体（C级） | D8: 各媒体 | E8: 2026-03至2026-09 | F8: 全期间 | G8: IPO进展、上市首日行情、2026H1业绩解读、股东结构（王兴兴持股23.8216%）等交叉验证信息 | H8: egs.stcn.com/news/detail/2255406.html 等多篇文章 | I8: 用于交叉验证与背景信息，关键数据已与A级来源比对
A9: 7 | B9: 华源证券等券商研究报告（媒体/知识库转引） | C9: 券商研究（C级） | D9: 华源证券等 | E9: 2026年 | F9: 2023-2025、2026Q1 | G9: 费用率拆分（销售/管理/研发/财务）、扣非净利率、分产品毛利率、2026Q2盈利预测 | H9: 第三方知识库转引 | I9: 未经原文核验，仅作交叉参考；预测内容已归入“预测参考(非事实)”表

Sheet 原始数据-财务
A1: 原始财务数据（单位：人民币万元；百分比为小数格式）
A2: 指标 | B2: 单位 | C2: 2022年度 | D2: 2023年度 | E2: 2024年度 | F2: 2025年度 | G2: 2025H1 | H2: 2025Q1-3 | I2: 2026Q1 | J2: 2026H1 | K2: 数据性质 | L2: 备注（口径与来源）
A3: 营业收入 | B3: 万元 | C3: 12291.95 | D3: 15913.44 | E3: 39237.06 | F3: 169926.93 | G3: 77560 | H3: 116700 | I3: 42284.05 | J3: 115224.56 | K3: 披露为主 | L3: 2022-2024及2026H1为交易所/数据库精确值；2025年度为上市公告书口径169,926.93万元（申报稿口径17.08亿元，见说明表）；2025Q1-3为招股书约数11.67亿元；2025H1为按2026H1同比+48.54%反推的推算值；2026Q1为一季报精确值42,284.05万元。
A4: 归母净利润 | B4: 万元 | C4: -2210.05 | D4: -1114.51 | E4: 9450.18 | F4: 27800 | G4: -3202.45 | H4: 10500 | J4: 27400 | K4: 披露为主 | L4: 2022-2024及2025H1、2026H1（273,999,911.92元）为披露值；2025年度约2.78亿元为媒体转引（另有含少数股东口径约2.88亿元），精确值待核年报；2025Q1-3约1.05亿元。
A5: 净利润（含少数股东） | B5: 万元 | E5: 9547.47 | F5: 28800 | K5: 媒体报道 | L5: 2024年9,547.47万元、2025年约2.88亿元（媒体转引招股书/上会稿），与归母口径差异为少数股东损益。
A6: 扣非归母净利润 | B6: 万元 | C6: -807 | D6: -1801.91 | E6: 7750 | F6: 59075.28 | G6: 30250 | H6: 43100 | I6: 4025.36 | J6: 24400 | K6: 披露为主 | L6: 2025年度59,075.28万元为上市公告书口径；2024年7,750万元为申报稿披露（按2025年+652.78%推算约7,845万元，存在小幅版本差异）；2025H1为按2026H1同比-19.34%反推的推算值；2026Q1为4,025.36万元。
A7: 主营业务毛利率 | B7: % | C7: 0.4418 | D7: 0.4422 | E7: 0.5641 | F7: 0.6027 | H7: 0.5945 | K7: 披露（招股书） | L7: 招股书申报稿口径：2022/2023/2024/2025Q1-3分别为44.18%/44.22%/56.41%/59.45%；2025年度60.27%（申报稿），上会稿口径为60.13%，存在版本差异。
A8: 销售毛利率（整体） | B8: % | D8: 0.4475 | E8: 0.5698 | F8: 0.6044 | I8: 0.5842 | J8: 0.5601 | K8: 披露（报表口径） | L8: 整体报表口径（含其他业务）：2023年44.75%、2024年56.98%、2025年60.44%、2026Q1为58.42%、2026H1为56.01%。
A9: 研发费用 | B9: 万元 | D9: 4995.18 | E9: 6983 | F9: 14496.56 | G9: 5387 | H9: 9021 | I9: 6319.31 | J9: 13590.65 | K9: 披露/推算混合 | L9: 2023年4,995.18万元、2025年14,496.56万元、2026Q1为6,319.31万元、2026H1为13,590.65万元（披露值）；2024年约6,983万元为按研发费用率17.8%推算；2025H1为5,387万元（据2026H1同比+152%披露值）。
A10: 销售费用 | B10: 万元 | F10: 14100 | J10: 16400 | K10: 披露（约数） | L10: 2025年约1.41亿元（费用率8.31%）；2026H1约1.64亿元，已超过2025年全年水平。
A11: 经营活动现金流净额 | B11: 万元 | E11: 19000 | F11: 67000 | K11: 约数/推算 | L11: 2025年净流入超6.7亿元（约数）；2024年约1.9亿元为按“2025年较2024年增加4.8亿元”反推，需以现金流量表为准。
A12: 资产总额 | B12: 万元 | F12: 320800 | J12: 384500 | K12: 披露/推算混合 | L12: 2026-06-30为38.45亿元（披露，较上年末+19.85%）；2025年末32.08亿元为反推值。
A13: 流动资产 | B13: 万元 | F13: 221900 | J13: 288800 | K13: 披露/推算混合 | L13: 2026-06-30为28.88亿元（披露，较上年末+30.13%）；2025年末22.19亿元为反推值。
A14: 股份支付费用（非经常性） | B14: 万元 | F14: 34906.55 | G14: 34900 | K14: 披露 | L14: 2025年确认34,906.55万元（股权激励平台上海宇翼增资），主要在2025H1确认，导致2025H1归母净利润为负而扣非为正。

Sheet 原始数据-业务
A1: 业务与经营数据（单位：人民币万元；资料截止2026-08-30）
A3: 一、2025年度主营业务收入结构（按产品，年报口径）
A4: 产品 | B4: 收入（万元） | C4: 占比 | D4: 备注
A5: 人形机器人 | B5: 86783.19 | C5: =IF(OR($B$10="",$B$10=0),"",B5/$B$10) -> 0.51070887 | D5: 2025年占比51.07%，第一大收入来源；全年出货超5,500台（纯人形，不含轮式双臂），出货量全球第一
A6: 四足机器人 | B6: 69762.56 | C6: =IF(OR($B$10="",$B$10=0),"",B6/$B$10) -> 0.41054446 | D6: 占比41.05%；B系列行业级+Go系列消费级，2022-2025Q3累计销量超3万台
A7: 机器人组件 | B7: 10373.67 | C7: =IF(OR($B$10="",$B$10=0),"",B7/$B$10) -> 0.061047828 | D7: 占比6.10%；关节模组、灵巧手、协作机械臂、感知传感器等
A8: 其他业务 | B8: 2315.84 | C8: =IF(OR($B$10="",$B$10=0),"",B8/$B$10) -> 0.013628446 | D8: 占比1.36%
A9: 其他 | B9: 691.67 | C9: =IF(OR($B$10="",$B$10=0),"",B9/$B$10) -> 0.0040703966 | D9: 占比0.41%
A10: 合计 | B10: =SUM(B5:B9) -> 169926.93 | C10: =IF(OR(B10="",B10=0),"",1) -> 1
A12: 二、2025年度收入结构（按地域，年报口径）
A13: 地域 | B13: 收入（万元） | C13: 占比 | D13: 备注
A14: 境内 | B14: 94445.56 | C14: =IF(OR($B$17="",$B$17=0),"",B14/$B$17) -> 0.55580101 | D14: 占比55.58%；2025年春晚演出后境内需求显著放量，为2022年以来境内占比首次过半
A15: 境外 | B15: 73165.53 | C15: =IF(OR($B$17="",$B$17=0),"",B15/$B$17) -> 0.43057054 | D15: 占比43.06%；2022-2024年境外收入占比均超50%，2025年结构反转
A16: 其他业务 | B16: 2315.84 | C16: =IF(OR($B$17="",$B$17=0),"",B16/$B$17) -> 0.013628446 | D16: 占比1.36%
A17: 合计 | B17: =SUM(B14:B16) -> 169926.93 | C17: =IF(OR(B17="",B17=0),"",1) -> 1
A19: 三、收入结构历史趋势（占主营业务收入比例）
A20: 年度 | B20: 人形机器人占比 | C20: 四足机器人占比 | D20: 境外收入占比 | E20: 备注
A21: 2022年度 | C21: 0.7657 | E21: 四足机器人占总营收76.57%；境外收入占比超50%（精确值待核）
A22: 2023年度 | B22: 0.0188 | E22: 首款人形H1上市当年，人形收入占比1.88%；境外占比超50%
A23: 2024年度 | B23: 0.276 | E23: 中型人形G1放量，人形占比提升至27.6%；境外占比超50%
A24: 2025Q1-3 | B24: 0.5153 | D24: 0.392 | E24: 人形收入5.95亿元（+642.38%）首次反超四足；境内占比60.8%
A25: 2025年度 | B25: 0.5107 | C25: 0.4105 | D25: 0.4306 | E25: 人形51.07%/四足41.05%/境外43.06%（年报口径）
A27: 四、销量与产品动态（招股书/官方口径）
A28: 指标 | B28: 数值 | C28: 单位 | D28: 备注
A29: 四足机器人累计销量（2022-2025Q3） | B29: 30000 | C29: 台 | D29: 超3万台，全球四足机器人市场第一梯队
A30: 2025年度人形机器人出货量 | B30: 5500 | C30: 台 | D30: 超5,500台（纯人形，不含轮式双臂），出货量全球第一（约数）
A31: 2025Q1-3人形机器人销量 | B31: 3551 | C31: 台 | D31: 同比增长1054.8%
A32: 2025Q1-3人形机器人收入 | B32: 59500 | C32: 万元 | D32: 同比增长642.38%
A33: 2025Q1-3四足机器人收入 | B33: 48800 | C33: 万元 | D33: 同比增长182.22%
A34: 2025Q1-3人形收入中科研教育领域占比 | B34: 0.736 | C34: % | D34: 科研教育为当前最主要下游场景；海外收入占比超40%
A36: 五、分产品毛利率（招股书披露口径）
A37: 产品 | B37: 2023年度 | C37: 2024年度 | D37: 2025Q1-3 | E37: 备注
A38: 人形机器人 | B38: 0.877 | C38: 0.684 | D38: 0.629 | E38: 毛利率随G1放量与主动降价而收窄，但仍显著高于整体水平
A39: 机器人组件 | B39: 0.488 | C39: 0.569 | D39: 0.604 | E39: 组件毛利率稳步提升
A41: 六、IPO与上市信息（截至2026-08-30）
A42: 项目 | B42: 内容 | C42: 备注
A43: IPO受理日期 | B43: 2026-03-20 | C43: 上交所科创板受理，适用“预先审阅”机制
A44: 上市委会议通过 | B44: 2026-06-01 | C44: 受理至过会约70余天
A45: 上市日期 | B45: 2026-08-19 | C45: 科创板，A股“人形机器人整机第一股”
A46: 证券代码/简称 | B46: 688836.SH 宇树科技-W | C46: 上市后未盈利?否——已实现盈利；-W为特殊标识（加权表决权/类似安排，以公告为准）
...

Sheet 核心计算
A1: 核心计算（公式联动“原始数据-财务”，修改原始数据后自动更新）
A2: 指标 | B2: 单位 | C2: 2022年度 | D2: 2023年度 | E2: 2024年度 | F2: 2025年度 | G2: 2026H1 | H2: 计算口径说明
A3: 营业收入同比增速 | B3: % | D3: =IF(OR('原始数据-财务'!C3="",'原始数据-财务'!C3=0),"",'原始数据-财务'!D3/'原始数据-财务'!C3-1) -> 0.2946229 | E3: =IF(OR('原始数据-财务'!D3="",'原始数据-财务'!D3=0),"",'原始数据-财务'!E3/'原始数据-财务'!D3-1) -> 1.4656554 | F3: =IF(OR('原始数据-财务'!E3="",'原始数据-财务'!E3=0),"",'原始数据-财务'!F3/'原始数据-财务'!E3-1) -> 3.3307763 | G3: =IF(OR('原始数据-财务'!G3="",'原始数据-财务'!G3=0),"",'原始数据-财务'!J3/'原始数据-财务'!G3-1) -> 0.48561836 | H3: 2026H1为对2025H1（推算值）的同比；2025年度同比对应招股书披露+332.64%~335.36%（版本差异）
A4: 归母净利率 | B4: % | C4: =IF(OR('原始数据-财务'!C3="",'原始数据-财务'!C3=0),"",'原始数据-财务'!C4/'原始数据-财务'!C3) -> -0.17979653 | D4: =IF(OR('原始数据-财务'!D3="",'原始数据-财务'!D3=0),"",'原始数据-财务'!D4/'原始数据-财务'!D3) -> -0.070035769 | E4: =IF(OR('原始数据-财务'!E3="",'原始数据-财务'!E3=0),"",'原始数据-财务'!E4/'原始数据-财务'!E3) -> 0.24084832 | F4: =IF(OR('原始数据-财务'!F3="",'原始数据-财务'!F3=0),"",'原始数据-财务'!F4/'原始数据-财务'!F3) -> 0.16359973 | G4: =IF(OR('原始数据-财务'!J3="",'原始数据-财务'!J3=0),"",'原始数据-财务'!J4/'原始数据-财务'!J3) -> 0.23779653 | H4: 归母净利润/营业收入
A5: 扣非归母净利率 | B5: % | C5: =IF(OR('原始数据-财务'!C3="",'原始数据-财务'!C3=0),"",'原始数据-财务'!C6/'原始数据-财务'!C3) -> -0.065652724 | D5: =IF(OR('原始数据-财务'!D3="",'原始数据-财务'!D3=0),"",'原始数据-财务'!D6/'原始数据-财务'!D3) -> -0.11323196 | E5: =IF(OR('原始数据-财务'!E3="",'原始数据-财务'!E3=0),"",'原始数据-财务'!E6/'原始数据-财务'!E3) -> 0.19751735 | F5: =IF(OR('原始数据-财务'!F3="",'原始数据-财务'!F3=0),"",'原始数据-财务'!F6/'原始数据-财务'!F3) -> 0.34765108 | G5: =IF(OR('原始数据-财务'!J3="",'原始数据-财务'!J3=0),"",'原始数据-财务'!J6/'原始数据-财务'!J3) -> 0.21176041 | H5: 扣非归母净利润/营业收入；2025年度约34.77%（券商口径34.8%一致）
A6: 研发费用率 | B6: % | D6: =IF(OR('原始数据-财务'!D3="",'原始数据-财务'!D3=0),"",'原始数据-财务'!D9/'原始数据-财务'!D3) -> 0.31389693 | E6: =IF(OR('原始数据-财务'!E3="",'原始数据-财务'!E3=0),"",'原始数据-财务'!E9/'原始数据-财务'!E3) -> 0.1779695 | F6: =IF(OR('原始数据-财务'!F3="",'原始数据-财务'!F3=0),"",'原始数据-财务'!F9/'原始数据-财务'!F3) -> 0.085310551 | G6: =IF(OR('原始数据-财务'!J3="",'原始数据-财务'!J3=0),"",'原始数据-财务'!J9/'原始数据-财务'!J3) -> 0.11794925 | H6: 研发费用/营业收入；2024年研发费用为推算值，结果仅供参考
A7: 扣非归母净利润同比增速 | B7: % | E7: =IF(OR('原始数据-财务'!D6="",'原始数据-财务'!D6=0),"",'原始数据-财务'!E6/'原始数据-财务'!D6-1) -> -5.3009917 | F7: =IF(OR('原始数据-财务'!E6="",'原始数据-财务'!E6=0),"",'原始数据-财务'!F6/'原始数据-财务'!E6-1) -> 6.6226168 | G7: =IF(OR('原始数据-财务'!G6="",'原始数据-财务'!G6=0),"",'原始数据-财务'!J6/'原始数据-财务'!G6-1) -> -0.19338843 | H7: 2026H1为对2025H1（推算值）的同比，与披露值-19.34%一致；2025年度同比披露口径为+652.78%~674.29%
A9: 关键综合指标
A10: 指标 | B10: 数值 | C10: 单位 | D10: 计算说明
A11: 2022-2025营业收入CAGR | B11: =IF(OR('原始数据-财务'!C3="",'原始数据-财务'!C3=0,'原始数据-财务'!F3="",'原始数据-财务'!F3=0),"",('原始数据-财务'!F3/'原始数据-财务'!C3)^(1/3)-1) -> 1.4000142 | C11: % | D11: 2022→2025三年复合增速；招股书按2025Q1-3年化口径披露为133.09%（口径不同）
A12: 2023-2025营业收入CAGR | B12: =IF(OR('原始数据-财务'!D3="",'原始数据-财务'!D3=0,'原始数据-财务'!F3="",'原始数据-财务'!F3=0),"",('原始数据-财务'!F3/'原始数据-财务'!D3)^(1/2)-1) -> 2.2677519 | C12: % | D12: 2023→2025两年复合增速
A13: 2025年营收相对2022年倍数 | B13: =IF(OR('原始数据-财务'!C3="",'原始数据-财务'!C3=0),"",'原始数据-财务'!F3/'原始数据-财务'!C3) -> 13.824245 | C13: 倍 | D13: 三年约13.8倍
A14: 2025年度扣非归母净利率 | B14: =IF(OR(F5="",F5=0),"",F5) -> 0.34765108 | C14: % | D14: 引用上行计算结果
A15: 2026H1扣非归母净利率 | B15: =IF(OR(G5="",G5=0),"",G5) -> 0.21176041 | C15: % | D15: 2026H1扣非2.44亿元/营收11.52亿元
A16: 2026Q1扣非归母净利率 | B16: =IF(OR('原始数据-财务'!I3="",'原始数据-财务'!I3=0),"",'原始数据-财务'!I6/'原始数据-财务'!I3) -> 0.095198071 | C16: % | D16: 2026Q1扣非净利率约9.52%，受研发与销售费用前置影响偏低
A17: 2026Q1营业收入同比增速 | B17: 0.6849 | C17: % | D17: 公司一季报披露值（+68.49%），非本表推算
A18: 2026H1研发费用同比增速 | B18: =IF(OR('原始数据-财务'!G9="",'原始数据-财务'!G9=0),"",'原始数据-财务'!J9/'原始数据-财务'!G9-1) -> 1.5228606 | C18: % | D18: 与披露口径+152%（约1.52倍）一致
A19: 2026H1销售费用相对2025全年 | B19: =IF(OR('原始数据-财务'!F10="",'原始数据-财务'!F10=0),"",'原始数据-财务'!J10/'原始数据-财务'!F10) -> 1.1631206 | C19: 倍 | D19: 2026H1销售费用已超2025年全年
A20: 2025年度销售费用率 | B20: =IF(OR('原始数据-财务'!F3="",'原始数据-财务'!F3=0),"",'原始数据-财务'!F10/'原始数据-财务'!F3) -> 0.082976842 | C20: % | D20: 约8.31%（券商口径一致）
A21: 2025年人形机器人收入占比 | B21: =IF(OR('原始数据-业务'!B10="",'原始数据-业务'!B10=0),"",'原始数据-业务'!B5/'原始数据-业务'!B10) -> 0.51070887 | C21: % | D21: 引用业务表计算结果
A22: 2026H1资产总额较2025年末增幅 | B22: =IF(OR('原始数据-财务'!F12="",'原始数据-财务'!F12=0),"",'原始数据-财务'!J12/'原始数据-财务'!F12-1) -> 0.19856608 | C22: % | D22: 与披露值+19.85%一致（2025年末数为反推值）

Sheet 趋势图表
A1: 趋势图表（数据块引用原始数据与核心计算，图表随数据联动）
A3: 图1数据：营业收入与增速（年度）
A4: 年度 | B4: 营业收入（亿元） | C4: 同比增速（%）
A5: 2022 | B5: ='原始数据-财务'!C3/10000 -> 1.229195
A6: 2023 | B6: ='原始数据-财务'!D3/10000 -> 1.591344 | C6: ='核心计算'!D3*100 -> 29.46229
A7: 2024 | B7: ='原始数据-财务'!E3/10000 -> 3.923706 | C7: ='核心计算'!E3*100 -> 146.56554
A8: 2025 | B8: ='原始数据-财务'!F3/10000 -> 16.992693 | C8: ='核心计算'!F3*100 -> 333.07763
A11: 图2数据：归母净利润与扣非归母净利润（年度）
A12: 年度 | B12: 归母净利润（亿元） | C12: 扣非归母净利润（亿元）
A13: 2022 | B13: ='原始数据-财务'!C4/10000 -> -0.221005 | C13: ='原始数据-财务'!C6/10000 -> -0.0807
A14: 2023 | B14: ='原始数据-财务'!D4/10000 -> -0.111451 | C14: ='原始数据-财务'!D6/10000 -> -0.180191
A15: 2024 | B15: ='原始数据-财务'!E4/10000 -> 0.945018 | C15: ='原始数据-财务'!E6/10000 -> 0.775
A16: 2025 | B16: ='原始数据-财务'!F4/10000 -> 2.78 | C16: ='原始数据-财务'!F6/10000 -> 5.907528
A19: 图3数据：利润率趋势（年度）
A20: 年度 | B20: 主营业务毛利率（%） | C20: 扣非归母净利率（%）
A21: 2022 | B21: =IF('原始数据-财务'!C7="","",'原始数据-财务'!C7*100) -> 44.18 | C21: =IF('核心计算'!C5="","",'核心计算'!C5*100) -> -6.5652724
A22: 2023 | B22: =IF('原始数据-财务'!D7="","",'原始数据-财务'!D7*100) -> 44.22 | C22: =IF('核心计算'!D5="","",'核心计算'!D5*100) -> -11.323196
A23: 2024 | B23: =IF('原始数据-财务'!E7="","",'原始数据-财务'!E7*100) -> 56.41 | C23: =IF('核心计算'!E5="","",'核心计算'!E5*100) -> 19.751735
A24: 2025 | B24: =IF('原始数据-财务'!F7="","",'原始数据-财务'!F7*100) -> 60.27 | C24: =IF('核心计算'!F5="","",'核心计算'!F5*100) -> 34.765108
A27: 图4数据：2025年度收入结构（产品）
A28: 产品 | B28: 收入（万元）
A29: 人形机器人 | B29: ='原始数据-业务'!B5 -> 86783.19
A30: 四足机器人 | B30: ='原始数据-业务'!B6 -> 69762.56
A31: 机器人组件 | B31: ='原始数据-业务'!B7 -> 10373.67
A32: 其他 | B32: =SUM('原始数据-业务'!B8:B9) -> 3007.51
A35: 图5数据：人形机器人收入占比（年度）
A36: 年度 | B36: 人形机器人收入占比（%）
A37: 2023 | B37: =IF('原始数据-业务'!B22="","",'原始数据-业务'!B22*100) -> 1.88
A38: 2024 | B38: =IF('原始数据-业务'!B23="","",'原始数据-业务'!B23*100) -> 27.6
A39: 2025 | B39: =IF('原始数据-业务'!B25="","",'原始数据-业务'!B25*100) -> 51.07

Sheet 分析结论
A1: 分析结论（区分事实、计算结果与分析判断）
A2: 序号 | B2: 结论要点 | C2: 类型 | D2: 依据（数据/来源）
A3: 1 | B3: 营收三年约13.8倍高速扩张：营业收入由2022年1.23亿元增至2025年16.99亿元，2022-2025年CAGR约140%，2025年同比+333%（招股书披露区间+332.64%~335.36%）。 | C3: 计算结果 | D3: 原始数据-财务、核心计算；招股书/年报
A4: 2 | B4: 2024年起扭亏为盈并快速放大：归母净利润由2023年-1,114.51万元升至2024年9,450.18万元、2025年约2.78亿元；扣非归母净利润由-1,801.91万元升至2025年59,075.28万元。 | C4: 事实（含约数） | D4: 招股书、上市公告书
A5: 3 | B5: 盈利质量持续改善：主营业务毛利率由2022年44.18%升至2025年约60.27%（整体口径60.44%），扣非净利率2025年达约34.8%，在全球人形机器人公司中属少数实现规模化盈利的样本。 | C5: 计算结果+判断 | D5: 招股书、年报、核心计算
A6: 4 | B6: 收入结构完成切换：人形机器人收入占比由2023年1.88%→2024年27.6%→2025年51.07%，2025年首次超过四足机器人成为第一大收入来源；2025年人形出货超5,500台，居全球第一。 | C6: 事实 | D6: 招股书、年报
A7: 5 | B7: 市场结构反转：2022-2024年境外收入占比均超50%，2025年境内占比升至55.58%（春晚等品牌事件带动），境外降至43.06%，内需成为主要增量。 | C7: 事实+判断 | D7: 招股书、年报
A8: 6 | B8: 2026年增速换挡：2026Q1营收同比+68.49%、2026H1同比+48.54%，较2025年+333%明显回落；公司归因于营收基数大幅提升、行业热度缓和及竞争加剧。 | C8: 事实 | D8: 一季报、上市公告书
A9: 7 | B9: 阶段性的“增收不增利”信号：2026Q1扣非同比-52.55%、2026H1扣非同比-19.34%；2026H1研发费用1.36亿元（+152%）、销售费用1.64亿元（已超2025年全年），费用前置是主因，2026Q2扣非净利率已回升（招股书预告区间31.11%-34.42%）。 | C9: 事实+判断 | D9: 一季报、上市公告书、券商拆分
A10: 8 | B10: 归母与扣非差异主要来自股份支付：2025年确认非经常性股份支付34,906.55万元（主要在2025H1），导致2025H1归母-3,202.45万元而扣非为正，阅读利润数据时须区分口径。 | C10: 事实 | D10: 上市公告书、招股书
A11: 9 | B11: 盈利有现金流支撑：2025年经营活动现金净流入超6.7亿元，较2024年增加约4.8亿元；2026-06-30总资产38.45亿元（较上年末+19.85%）、流动资产28.88亿元，资金面稳健。 | C11: 事实（含约数） | D11: 招股书、上市公告书
A12: 10 | B12: 下游场景仍以科研教育为主：2025Q1-3人形收入中科研教育领域占比73.6%，工业与商业场景的规模化落地仍是未来增长的关键变量。 | C12: 事实+判断 | D12: 招股书（媒体转引）
A13: 11 | B13: 竞争与估值风险：国内整车/消费电子企业入局人形机器人，产品定价、份额与利润率面临潜在压力；发行市盈率约219倍，上市首日开盘1,100元/股后股价大幅回落，估值消化依赖业绩持续兑现。 | C13: 事实+判断 | D13: 招股书风险提示、上市公告书、公开行情
A14: 12 | B14: 总体判断：公司处于“高速成长+盈利兑现+结构切换”阶段，2026年上半年呈现增速换挡与费用前置的组合特征；后续重点跟踪人形机器人工业场景订单、毛利率走势及费用率回归水平。 | C14: 分析判断 | D14: 本底稿综合
A16: 声明
A17: 以上结论基于截至2026-08-30的公开资料；标注“约数/推算”的数据请先按“说明与口径”表中的待核验清单核对披露原文后再对外使用；券商预测数据见“预测参考(非事实)”表，均非已发生事实。

Sheet 预测参考(非事实)
A1: 机构预测参考——以下均为预测/前瞻陈述，不是已发生的事实
A2: ⚠ 特别提示：本表全部数据为机构预测或公司业绩预告，截至2026-08-30均未经审计、未实际发生，仅作方向性参考，不得作为历史事实引用。
A4: 机构 | B4: 指标 | C4: 2026E | D4: 2027E | E4: 2028E | F4: 数据性质
A5: 野村证券（媒体报道转引） | B5: 营业收入（亿元） | C5: 26.87 | D5: 53.96 | E5: 131.84 | F5: 机构预测，非事实
A6: 招商证券（媒体报道转引） | B6: 营业收入（亿元） | C6: 30.97 | D6: 49.6 | E6: 76.83 | F6: 机构预测，非事实
A8: 业绩预告与实际披露对照（招股书预告 vs 上市公告书实际）
A9: 项目 | B9: 招股书预告区间（未经审计） | C9: 实际披露（上市公告书） | D9: 差异说明
A10: 2026H1营业收入（亿元） | B10: 10.52 - 11.28 | C10: 11.52 | D10: 实际超出预告区间上限，收入端强于预告
A11: 2026H1扣非归母净利润（亿元） | B11: 2.36 - 2.83 | C11: 2.44 | D11: 实际落于预告区间内
A12: 2026Q2扣非净利率（推算） | B12: 31.11% - 34.42%（预告推算） | C12: 2026H1整体扣非净利率约21.2% | D12: Q1受费用前置拖累，Q2回升（据券商拆分）
A14: 注：野村/招商证券预测来自媒体转引，未经研报原文核验；上表“实际披露”列才是已发生事实。
