Workbook

Sheet 说明与来源
A1: 宇树科技股份有限公司（688836.SH）经营与财务表现分析底稿
A2: 资料截止时间：2026-08-30 | 编制日期：2026-09-04 | 单位：除特别说明外为人民币万元
A4: 一、口径说明
A5: 报告期 | B5: 2023年度、2024年度、2025年度（经审计，容诚审字[2026]230Z1692号，标准无保留意见）
A6: 审阅期间 | B6: 2026年1-3月（经审阅，容诚阅字[2026]230Z0038号）
A7: 未审计期间 | B7: 2026年1-6月（未经审计，经第一届董事会第二十二次会议审议，见上市公告书附件二）
A8: 预测数据 | B8: 招股说明书所载2026年1-6月预计数据为管理层估计，未经审计或审阅，不构成盈利预测或业绩承诺；本底稿以黄底单独列示并与实际数对照，绝不混同于已发生事实
A9: 金额单位 | B9: 统一为人民币万元；每股/单价数据为元；销量为台；比率以%列示（单元格存储为小数）
A10: 颜色图例 | B10: 蓝字=披露原文硬编码输入；黑字=本表公式；绿字=跨表引用公式；黄底=预测数据
A11: 可编辑性 | B11: 修改蓝字输入后，全部公式与图表自动重算
A13: 二、资料来源清单
A14: 编号 | B14: 资料名称 | C14: 披露/批复日期 | D14: 出具方 | E14: 用途 | F14: 获取方式
A15: S1 | B15: 首次公开发行股票科创板上市公告书 | C15: 2026-08-18 | D15: 宇树科技/中信证券 | E15: IPO要素、2026H1未审计报表、2025年末比较数据 | F15: 上交所网站披露;PDF镜像 stockmc.xueqiu.com/202608/688836_20260818_ROD1.pdf
A16: S2 | B16: 首次公开发行股票并在科创板上市招股说明书(上会稿) | C16: 2026-05 | D16: 宇树科技 | E16: 报告期2023-2025财务与业务数据、产品结构、募投 | F16: 上交所披露;镜像 pdf.dfcfw.com/pdf/H2_AN202605251822861710_1.pdf
A17: S3 | B17: 招股说明书(注册稿)及注册批复 证监许可〔2026〕1612号 | C17: 2026-07-01 | D17: 中国证监会 | E17: 法定生效版本;关键数字已与S1/S2核对一致 | F17: 上交所网站,建议人工复核
A18: S4 | B18: 审计报告 容诚审字[2026]230Z1692号 | C18: 2026 | D18: 容诚会计师事务所 | E18: 2023-2025审计 | F18: 招股意向书附录
A19: S5 | B19: 审阅报告 容诚阅字[2026]230Z0038号 | C19: 2026 | D19: 容诚会计师事务所 | E19: 2026年1-3月审阅 | F19: 招股意向书附录
A20: S6 | B20: 上市公告书附件二:2026年1-6月财务会计报表 | C20: 2026-08-18 | D20: 宇树科技(未经审计) | E20: 2026H1三大报表 | F20: 同S1
A22: 三、边界与需人工核验事项
A23: 1) 2022年度营收1.23亿元等仅见于媒体报道,未纳入正式表(招股书报告期为2023-2025)。
A24: 2) 上市首日(2026-08-19)及后续二级市场涨跌幅属行情数据,非披露财务口径,本底稿不纳入;如需要请以上交所行情为准。
A25: 3) 本底稿招股书数据取自上会稿镜像;注册稿为法定文本,关键数字(2025营收169,926.93万元、扣非归母59,075.28万元、主营毛利率60.13%、研发费用14,496.56万元)已与上市公告书交叉验证一致,仍建议以注册稿原文页码复核。
A26: 4) 2026H1数据未经审计;2026Q1为审阅数。

Sheet 原始数据-年度
A1: 原始数据·年度（2023-2025，经审计）
A2: 单位：万元（每股/单价除外） 来源：S2招股说明书(上会稿)/S1上市公告书
A3: 项目 | B3: 单位 | C3: 2023 | D3: 2024 | E3: 2025 | F3: 来源/备注
A4: 营业收入 | B4: 万元 | C4: 15913.44 | D4: 78554.14 | E4: 169926.93 | F4: S2/S1
A5: 主营业务收入 | B5: 万元 | C5: 15753.65 | D5: 38767.28 | E5: 167611.09 | F5: S2
A6: －四足机器人收入 | B6: 万元 | C6: 11938.09 | D6: 23054.37 | E6: 69762.56 | F6: S2
A7: －人形机器人收入 | B7: 万元 | C7: 296.71 | D7: 10729.76 | E7: 86783.19 | F7: S2
A8: －机器人组件收入 | B8: 万元 | C8: 2692.34 | D8: 4453.82 | E8: 10373.67 | F8: S2
A9: －其他收入 | B9: 万元 | C9: 826.51 | D9: 529.33 | E9: 691.67 | F9: S2
A10: 主营业务毛利率 | B10: % | C10: 0.4422 | D10: 0.5674 | E10: 0.6013 | F10: S2
A11: －四足机器人毛利率 | B11: % | C11: 0.4371 | D11: 0.5165 | E11: 0.5672 | F11: S2
A12: －人形机器人毛利率 | B12: % | C12: 0.8767 | D12: 0.6926 | E12: 0.6318 | F12: S2
A13: －组件毛利率 | B13: % | C13: 0.4876 | D13: 0.5694 | E13: 0.5936 | F13: S2
A14: －其他毛利率 | B14: % | C14: 0.2111 | D14: 0.2323 | E14: 0.3353 | F14: S2
A15: 综合毛利率 | B15: % | C15: 0.4475 | D15: 0.5722 | E15: 0.6044 | F15: S2同业比较表
... A33: 扣非加权平均ROE | B33: % | C33: -0.0592 | D33: 0.086 | E33: 0.287 | F33: S2
A34: 基本每股收益 | B34: 元 | E34: 0.76 | F34: S2
A35: 四足机器人销量 | B35: 台 | C35: 3121 | D35: 7136 | E35: 23037 | F35: S2
A36: 四足机器人单价 | B36: 万元/台 | C36: 3.83 | D36: 3.23 | E36: 3.03 | F36: S2
A37: 人形机器人销量 | B37: 台 | C37: 5 | D37: 412 | E37: 5215 | F37: S2
A38: 人形机器人单价 | B38: 万元/台 | C38: 59.34 | D38: 26.04 | E38: 16.64 | F38: S2
A39: 人形机器人出货量 | B39: 台 | E39: 5511 | F39: S2 全球第一
A40: 员工总数(年末) | B40: 人 | E40: 516 | F40: S2
A41: 研发人员(年末) | B41: 人 | E41: 184 | F41: S2 占比35.66%
A42: 美国市场收入占比 | B42: % | C42: 0.1839 | D42: 0.1954 | E42: 0.133 | F42: S1风险因素
A43: 前五大客户收入占比 | B43: % | C43: 0.1269 | D43: 0.1245 | E43: 0.1208 | F43: S2
A44: 线上销售收入占比 | B44: % | C44: 0.1314 | D44: 0.1039 | E44: 0.1072 | F44: S2

Sheet 原始数据-期间与IPO
A1: 原始数据·期间（审阅/未审计）与IPO要素
A3: 项目 | B3: 单位 | C3: 2025Q1 | D3: 2025H1 | E3: 2026Q1 | F3: 2026H1 | G3: 审计属性 | H3: 来源
A4: 营业收入 | B4: 万元 | C4: 25095.87 | D4: 77571.92 | E4: 42284.05 | F4: 115224.56 | G4: 25Q1审阅;25H1/26H1未审计 | H4: S2/S1
A5: 营业成本 | B5: 万元 | D5: 30907.39 | F5: 50688.51 | G5: 未审计 | H5: S1附件二
A6: 归母净利润 | B6: 万元 | C6: 9560.25 | D6: -3202.45 | E6: 5001.38 | F6: 27399.99 | G6: 同上 | H6: S2/S1
A7: 扣非归母净利润 | B7: 万元 | C7: 8483.65 | D7: 30243.35 | E7: 4025.36 | F7: 24393.03 | G7: 同上 | H7: S2/S1
A8: 经营活动现金流量净额 | B8: 万元 | D8: 34319.36 | E8: 3439.96 | F8: 23154.53 | G8: 同上 | H8: S2/S1
A9: 研发费用 | B9: 万元 | D9: 5386.9 | F9: 13590.65 | G9: 未审计 | H9: S1附件二
A10: 销售费用 | B10: 万元 | D10: 4685.11 | F10: 16407.27 | G10: 未审计 | H10: S1附件二
A11: 管理费用 | B11: 万元 | D11: 36399.38 | F11: 4208.48 | G11: 25H1含股份支付34,906.55 | H11: S1附件二
A12: 资产总额 | B12: 万元 | E12: 345907.18 | F12: 384546.94 | G12: 同上 | H12: S2/S1
A13: 归母所有者权益 | B13: 万元 | E13: 265533.55 | F13: 287998.48 | G13: 同上 | H13: S2/S1
A14: 基本每股收益 | B14: 元 | D14: -0.09 | F14: 0.75 | G14: 未审计 | H14: S1
A16: 2026年1-6月预计数据（招股书·预测·未经审计或审阅·不构成盈利预测）
A17: 项目 | B17: 单位 | C17: 预计下限 | D17: 预计上限 | E17: 上年同期 | F17: 同比区间 | G17: 属性 | H17: 来源
A18: 营业收入 | B18: 万元 | C18: 105200 | D18: 112800 | E18: 77571.92 | F18: +35.62%至+45.41% | G18: 预测 | H18: S2
A19: 归母净利润 | B19: 万元 | C19: 25800 | D19: 30600 | E19: -3202.45 | F19: 扭亏 | G19: 预测 | H19: S2
A20: 扣非归母净利润 | B20: 万元 | C20: 23600 | D20: 28300 | E20: 30243.35 | F20: -21.97%至-6.43% | G20: 预测 | H20: S2
A22: IPO与发行要素（S1上市公告书, 2026-08-18）
A23: 发行价格 | B23: 150.8 | C23: 元/股
A24: 发行后总股本 | B24: 40446.434 | C24: 万股
A25: 募集资金总额 | B25: 609932.22 | C25: 万元
A26: 募集资金净额 | B26: 591714.92 | C26: 万元
A27: 发行费用(不含税) | B27: 18217.31 | C27: 万元
A28: 发行市盈率(扣非孰低) | B28: 219.23 | C28: 倍
A29: 发行市净率 | B29: 7.16 | C29: 倍
A30: 发行后每股收益 | B30: 0.69 | C30: 元
A31: 发行后每股净资产 | B31: 21.07 | C31: 元
A32: 行业平均静态市盈率(T-3,C34) | B32: 38.56 | C32: 倍
A33: 拟使用募集资金(募投合计) | B33: 420171.12 | C33: 万元
A34: 发行前最后一轮投后估值(2025-06) | B34: 1270000 | C34: 万元
A36: 证券代码/上市板块/上市日期 | B36: 688836.SH / 科创板 / 2026-08-19
A37: 本次发行新股数量 | B37: 4,044.6434万股（占发行后总股本10%）
A38: 特别表决权: 王兴兴表决权 | B38: 发行前68.7816%; 发行后≤65.3090%
A39: 战略配售 | B39: 占20%; 社保基金/深度求索/昆仑资本/南网产融/天翼资本/启善投资(腾讯关联)/中证投资/员工资管计划, 限售12-36个月

Sheet 核心计算
A1: 核心计算（全部为公式，修改原始数据自动重算）
A3: 项目 | B3: 2024 | C3: 2025 | D3: 2026H1 | E3: 公式/口径
A4: 营业收入同比增速 | B4: ='原始数据-年度'!D4/'原始数据-年度'!C4-1 -> 3.9363393 | C4: ='原始数据-年度'!E4/'原始数据-年度'!D4-1 -> 1.1631824 | D4: ='原始数据-期间与IPO'!F4/'原始数据-期间与IPO'!D4-1 -> 0.48539007 | E4: 收入YoY
A5: 扣非归母净利润同比增速 | B5: =IF('原始数据-年度'!C22<0,"基期为负",'原始数据-年度'!D22/'原始数据-年度'!C22-1) -> 基期为负 | C5: =IF('原始数据-年度'!D22<0,"基期为负",'原始数据-年度'!E22/'原始数据-年度'!D22-1) -> 6.5277669 | D5: =IF('原始数据-期间与IPO'!D7<0,"基期为负",'原始数据-期间与IPO'!F7/'原始数据-期间与IPO'!D7-1) -> -0.19344153 | E5: 扣非YoY
A6: 归母净利润同比增速 | B6: =IF('原始数据-年度'!C21<0,"基期为负",'原始数据-年度'!D21/'原始数据-年度'!C21-1) -> 基期为负 | C6: =IF('原始数据-年度'!D21<0,"基期为负",'原始数据-年度'!E21/'原始数据-年度'!D21-1) -> 1.9139709 | D6: =IF('原始数据-期间与IPO'!D6<0,"基期为负",'原始数据-期间与IPO'!F6/'原始数据-期间与IPO'!D6-1) -> 基期为负 | E6: 归母YoY
A7: 人形机器人收入占主营比重 | B7: ='原始数据-年度'!D7/'原始数据-年度'!D5 -> 0.27677361 | C7: ='原始数据-年度'!E7/'原始数据-年度'!E5 -> 0.5177652 | E7: 人形/主营
A8: 四足机器人收入占主营比重 | B8: ='原始数据-年度'!D6/'原始数据-年度'!D5 -> 0.59468629 | C8: ='原始数据-年度'!E6/'原始数据-年度'!E5 -> 0.41621685 | E8: 四足/主营
A9: 四足机器人销量同比 | B9: ='原始数据-年度'!D35/'原始数据-年度'!C35-1 -> 1.2864467 | C9: ='原始数据-年度'!E35/'原始数据-年度'!D35-1 -> 2.2282791 | E9: 销量YoY
A10: 人形机器人销量同比 | B10: ='原始数据-年度'!D37/'原始数据-年度'!C37-1 -> 81.4 | C10: ='原始数据-年度'!E37/'原始数据-年度'!D37-1 -> 11.657767 | E10: 销量YoY
A11: 综合毛利率 | B11: ='原始数据-年度'!C15 -> 0.4475 | C11: ='原始数据-年度'!E15 -> 0.6044 | D11: =1-'原始数据-期间与IPO'!F5/'原始数据-期间与IPO'!F4 -> 0.56008936 | E11: 26H1按未审计成本推算
A12: 主营业务毛利率 | B12: ='原始数据-年度'!C10 -> 0.4422 | C12: ='原始数据-年度'!E10 -> 0.6013 | E12: 披露值
A13: 扣非净利率 | B13: ='原始数据-年度'!C22/'原始数据-年度'!C4 -> -0.11323196 | C13: ='原始数据-年度'!E22/'原始数据-年度'!E4 -> 0.34765108 | D13: ='原始数据-期间与IPO'!F7/'原始数据-期间与IPO'!F4 -> 0.21169992 | E13: 扣非/收入
A14: 归母净利率 | B14: ='原始数据-年度'!C21/'原始数据-年度'!C4 -> -0.070035769 | C14: ='原始数据-年度'!E21/'原始数据-年度'!E4 -> 0.16372361 | D14: ='原始数据-期间与IPO'!F6/'原始数据-期间与IPO'!F4 -> 0.23779644 | E14: 归母/收入
A15: 研发费用率 | B15: ='原始数据-年度'!C26/'原始数据-年度'!C4 -> 0.31389693 | C15: ='原始数据-年度'!E26/'原始数据-年度'!E4 -> 0.085310551 | D15: ='原始数据-期间与IPO'!F9/'原始数据-期间与IPO'!F4 -> 0.11794925 | E15: 研发/收入
A16: 销售费用率 | B16: ='原始数据-年度'!C24/'原始数据-年度'!C4 -> 0.23702166 | C16: ='原始数据-年度'!E24/'原始数据-年度'!E4 -> 0.083096423 | D16: ='原始数据-期间与IPO'!F10/'原始数据-期间与IPO'!F4 -> 0.14239386 | E16: 销售/收入
A17: 管理费用率 | B17: ='原始数据-年度'!C25/'原始数据-年度'!C4 -> 0.083753104 | C17: ='原始数据-年度'!E25/'原始数据-年度'!E4 -> 0.23515761 | D17: ='原始数据-期间与IPO'!F11/'原始数据-期间与IPO'!F4 -> 0.036524158 | E17: 25含股份支付
A18: 经营现金流/扣非净利润 | B18: =IF('原始数据-年度'!C22<=0,"基期为负",'原始数据-年度'!C28/'原始数据-年度'!C22) -> 基期为负 | C18: ='原始数据-年度'!E28/'原始数据-年度'!E22 -> 1.1341153 | D18: ='原始数据-期间与IPO'!F8/'原始数据-期间与IPO'!F7 -> 0.9492273 | E18: 盈利现金含量
A19: 营业收入CAGR(2023-2025) | C19: =('原始数据-年度'!E4/'原始数据-年度'!C4)^(1/2)-1 -> 2.2677519 | E19: (末/初)^(1/2)-1
A21: 单价交叉验证（计算值 vs 披露值）
A22: 项目 | B22: 2023 | C22: 2024 | D22: 2025 | E22: 口径
A23: 四足计算单价(万元/台) | B23: ='原始数据-年度'!C6/'原始数据-年度'!C35 -> 3.8250849 | C23: ='原始数据-年度'!D6/'原始数据-年度'!D35 -> 3.2307133 | D23: ='原始数据-年度'!E6/'原始数据-年度'!E35 -> 3.0282832 | E23: 收入/销量
A24: 四足披露单价(万元/台) | B24: ='原始数据-年度'!C36 -> 3.83 | C24: ='原始数据-年度'!D36 -> 3.23 | D24: ='原始数据-年度'!E36 -> 3.03 | E24: S2披露
A25: 差异 | B25: =B23-B24 -> -0.0049150913 | C25: =C23-C24 -> 0.00071328475 | D25: =D23-D24 -> -0.0017168034 | E25: 四舍五入差异
A26: 人形计算单价(万元/台) | B26: ='原始数据-年度'!C7/'原始数据-年度'!C37 -> 59.342 | C26: ='原始数据-年度'!D7/'原始数据-年度'!D37 -> 26.043107 | D26: ='原始数据-年度'!E7/'原始数据-年度'!E37 -> 16.641072 | E26: 收入/销量
A27: 人形披露单价(万元/台) | B27: ='原始数据-年度'!C38 -> 59.34 | C27: ='原始数据-年度'!D38 -> 26.04 | D27: ='原始数据-年度'!E38 -> 16.64 | E27: S2披露
A28: 差异 | B28: =B26-B27 -> 0.002 | C28: =C26-C27 -> 0.0031067961 | D28: =D26-D27 -> 0.001071908 | E28: 四舍五入差异
A30: 发行估值测算
A31: 发行市值(万元) | B31: ='原始数据-期间与IPO'!B23*'原始数据-期间与IPO'!B24 -> 6099322.2 | C31: 发行价×发行后总股本
A32: 发行市值/募资总额(倍) | B32: =B31/'原始数据-期间与IPO'!B25 -> 10 | C32: 应≈10(新股占10%)
A33: P/S(2025,发行市值口径,倍) | B33: =B31/'原始数据-年度'!E4 -> 35.893794 | C33: 市值/2025收入
A34: P/E交叉验证(倍) | B34: ='原始数据-期间与IPO'!B23/'原始数据-期间与IPO'!B30 -> 218.55072 | C34: 发行价/发行后EPS,披露219.23
A35: EPS交叉验证(元) | B35: ='原始数据-年度'!E21/'原始数据-期间与IPO'!B24 -> 0.68784927 | C35: 2025孰低归母/总股本,披露0.69
A36: 募资净额勾稽(万元) | B36: ='原始数据-期间与IPO'!B25-'原始数据-期间与IPO'!B27-'原始数据-期间与IPO'!B26 -> -0.01 | C36: 总额-费用-净额=0
A38: 预测 vs 实际（2026H1：招股书预计区间 vs 上市公告书实际·未审计）
A39: 项目 | B39: 预计下限 | C39: 预计上限 | D39: 实际 | E39: 对照结论
A40: 营业收入 | B40: ='原始数据-期间与IPO'!C18 -> 105200 | C40: ='原始数据-期间与IPO'!D18 -> 112800 | D40: ='原始数据-期间与IPO'!F4 -> 115224.56 | E40: =IF('原始数据-期间与IPO'!F4>'原始数据-期间与IPO'!D18,"实际高于预计上限",IF('原始数据-期间与IPO'!F4<'原始数据-期间与IPO'!C18,"低于下限","区间内")) -> 实际高于预计上限
A41: 归母净利润 | B41: ='原始数据-期间与IPO'!C19 -> 25800 | C41: ='原始数据-期间与IPO'!D19 -> 30600 | D41: ='原始数据-期间与IPO'!F6 -> 27399.99 | E41: =IF('原始数据-期间与IPO'!F6>'原始数据-期间与IPO'!D19,"实际高于预计上限",IF('原始数据-期间与IPO'!F6<'原始数据-期间与IPO'!C19,"低于下限","区间内")) -> 区间内
A42: 扣非归母净利润 | B42: ='原始数据-期间与IPO'!C20 -> 23600 | C42: ='原始数据-期间与IPO'!D20 -> 28300 | D42: ='原始数据-期间与IPO'!F7 -> 24393.03 | E42: =IF('原始数据-期间与IPO'!F7>'原始数据-期间与IPO'!D20,"实际高于预计上限",IF('原始数据-期间与IPO'!F7<'原始数据-期间与IPO'!C20,"低于下限","区间内")) -> 区间内
A44: 数据勾稽校验（结果应≈0）
A45: 2023 分产品收入合计-主营 | B45: =SUM('原始数据-年度'!C6:C9)-'原始数据-年度'!C5 -> 0
...

Sheet 趋势图表
A1: 趋势图表（引用“核心计算”图表数据区，随数据自动更新）

Sheet 分析结论
A1: 分析结论（基于上交所披露文件，资料截止2026-08-30）
A3: 一、成长性
A4: 2023-2025年营业收入由15,913.44万元增至169,926.93万元，CAGR 226.78%（公式校验与披露一致）；扣非归母净利润由-1,801.91万元增至59,075.28万元，2024年起扭亏并快速放大。2026H1实现营业收入115,224.56万元（+48.54%，未审计），增速较报告期年度复合水平明显放缓，与招股书风险提示一致。
A6: 二、收入结构
A7: 人形机器人2025年收入86,783.19万元、占主营51.78%，首次超过四足机器人（41.62%）成为第一收入来源；2025年人形销量5,215台、出货5,511台（披露为全球第一），四足销量23,037台。产品结构切换是毛利率与估值叙事的核心驱动。
A9: 三、盈利能力
A10: 主营业务毛利率44.22%→56.74%→60.13%，2025年综合毛利率60.44%高于同行业可比公司均值44.44%。其中人形毛利率87.67%→69.26%→63.18%逐年回落（G1占比提升叠加主动降价），四足毛利率43.71%→56.72%持续改善。2025年归母净利率仅约16.4%，主因股份支付34,906.55万元计入管理费用；扣非净利率34.8%更能反映经营层面盈利。
A12: 四、费用与投入
A13: 研发费用4,995.18→7,001.70→14,496.56万元，费用率31.39%→8.53%（规模效应）；2026H1研发13,590.65万元、同比增加8,203.74万元，叠加春晚等品牌推广使销售费用大增，导致2026H1扣非净利同比-19.34%、2026Q1扣非-52.55%——高投入期利润承压是现阶段主要特征。
A15: 五、现金流与资产负债表
A16: 2025年经营现金流净额66,998.18万元，约为扣非净利的1.13倍，盈利现金含量高；2026H1为23,154.53万元（-32.53%），系备货与费用付现增加。2026-06-30总资产384,546.94万元、归母权益287,998.48万元、合并资产负债率约25.1%，货币资金约14.92亿元，叠加募资净额591,714.92万元，资金储备充裕。
A18: 六、估值与发行
... A25: 招股书预计2026H1营收105,200-112,800万元，实际（未审计）115,224.56万元，高于预计上限；扣非实际24,393.03万元，落于预计区间23,600-28,300万元内。预测数据在本底稿中均以黄底单独列示，未与已发生数据混同。
