Workbook

Sheet 说明
A1: 宇树科技（688836.SH）经营与财务分析底稿——说明
A3: 用途：汇总宇树科技IPO、经营与财务公开数据，形成可追溯、可编辑的分析底稿，供投资研究参考。
A4: 资料截止日：2026-08-30。
A5: 单位约定：财务金额一律为人民币万元（每股价格为元/股；市值另标注为亿元处会注明；销量单位为台；单价为万元/台）。
A6: 报告期口径：以招股说明书注册稿/上市公告书口径（2023–2025年度经审计）为主分析口径；申报稿数据（2022年度、2025年1-9月）作补充并注明；2026年上半年数据来自上市公告书。
A7: 可靠性图例：✅=双源及以上交叉验证；⚠️=单一来源/倒算/约数，需人工核验；🔮=第三方预测，严禁写成事实。
A8: 公司无少数股东权益，净利润=归母净利润。2022年数据不在注册稿报告期内（申报稿口径）。
A9: 免责声明：预测类内容与事实严格区分（🔮第三方预测仅在允许位置出现并明确标注）；本底稿不构成投资建议。
A11: Sheet导航：
A12: 1 说明——本页，口径与图例约定。
A13: 2 资料来源——核心来源清单（首条为上交所688836公告列表，2026-08-30核验）。
A14: 3 原始数据_财务——数据块A–F：利润表/分产品/分地区/销量单价/资产负债/员工。
... A20: 9 待核验事项——单一来源/缺失数据清单及建议核验渠道。

Sheet 资料来源
A1: 资料来源（精选核心来源30条；首条为上交所公告列表，2026-08-30核验）
A2: 编号 | B2: 类型 | C2: 名称 | D2: 日期 | E2: 关键内容 | F2: URL | G2: 可靠性
A3: 1 | B3: 官方披露 | C3: 上海证券交易所官网·688836公司公告列表 | D3: 2026-08-30核验 | E3: 含招股意向书（2026-07-31）、发行公告、招股说明书正式稿（2026-08-14）、上市公告书（2026-08-18）等；经实地访问确认：截至2026-08-30公司未披露2026年半年报 | F3: https://www.sse.com.cn/assortment/stock/list/info/announcement/index.shtml?productId=688836 | G3: ✅已直接核验
A4: 2 | B4: 官方披露 | C4: 上交所·上市交易公告（上证公告(股票)[2026]25号） | D4: 2026-08-18 | E4: 2026-08-19上市，发行后总股本40,446.434万股 | F4: https://www.sse.com.cn/disclosure/announcement/listing/ipo/c/c_20260818_10829204.shtml | G4: ✅
A5: 3 | B5: 官方披露 | C5: 中国证券报·发行结果公告 | D5: 2026-08-14 | E5: 过会日2026-06-01、证监许可〔2026〕1612号、定价与配售细节、回拨机制 | F5: https://epaper.cs.com.cn/zgzqb/wap/html/2026-08/14/nw.D110000zgzqb_20260814_1-A08.htm | G5: ✅
A6: 4 | B6: 官方披露 | C6: 证券时报网·发行公告 | D6: 2026-08-07 | E6: 发行价150.80元/股、申购安排 | F6: https://epaper.stcn.com/con/202608/07/content_2958508.html | G6: ✅
A7: 5 | B7: 官方披露 | C7: 证券之星·上市公告书内容摘要 | D7: 2026-08-17 | E7: 募资净额591,714.92万元、王兴兴发行后持股21.4395%、流通股仅7.44%、上市标准 | F7: https://4g.stockstar.com/detail/AN2026081700035878 | G7: ✅
A8: 6 | B8: 权威媒体 | C8: 新华社《宇树科技，通过科创板上市审核》 | D8: 2026-06-01 | E8: 2023–2025营收1.59/3.93/16.99亿、净利润-1,114.51万/9,547.47万/2.78亿 | F8: 未获取 | G8: ✅
A9: 7 | B9: 权威媒体 | C9: 澎湃新闻（申报稿精确值报道） | D9: 2026-03-20 | E9: 申报稿：营收15,913.44万/39,237.06万/170,820.87万（经审阅） | F9: 未获取 | G9: ✅
A10: 8 | B10: 权威媒体 | C10: 长江商报《宇树科技营收17亿扣非6亿拟募42亿》 | D10: 2026-03-23 | E10: 总资产32.15亿/负债6.02亿/权益26.13亿、经营现金流/研发费用/境外收入/产销量全序列（部分为唯一来源） | F10: 未获取 | G10: ⚠️部分单一来源
A11: 9 | B11: 权威媒体 | C11: 证券时报/券商中国（上会稿与上市公告报道） | D11: 2026-05-25/2026-08-17 | E11: 主营毛利率44.22%/56.74%/60.13%、归母全序列、2026H1归母预计区间2.58–3.06亿 | F11: 未获取 | G11: ✅
A12: 10 | B12: 权威媒体 | C12: 中新经纬（证监会注册批复报道） | D12: 2026-07-02 | E12: 分产品收入：四足1.19/2.31/6.98亿，人形296.71万/1.07亿/8.68亿及占比（注册稿口径） | F12: 未获取 | G12: ✅
A13: 11 | B13: 权威媒体 | C13: 金融时报（申报稿/上会稿报道） | D13: 2026-03-21/2026-05-26 | E13: 归母净利润全序列；2025经营现金流6.70亿、2024年1.92亿、2026Q1现金流3,439.96万 | F13: 未获取 | G13: ✅
A14: 12 | B14: 权威媒体 | C14: 第一财经/无锡日报（上市首日报道） | D14: 2026-08-19 | E14: 上市首日行情+2026H1：营收11.52亿/归母2.74亿/扣非2.44亿 | F14: 未获取 | G14: ✅
... A32: 30 | B32: 机构数据 | C32: 彭博社/SAG《2026上半年全球人形机器人出货1.91万台》 | D32: 2026-08-10 | E32: 2026H1全球出货1.91万台、中国厂商占97%+；宇树5,900台被智元反超（第三方口径） | F32: 未获取 | G32: ⚠️机构口径差异

Sheet 原始数据_财务
A1: 原始数据_财务（数据块A–F；金额单位：万元人民币）
A3: 数据块A：利润表关键数据（单位：万元）
A4: 指标 | B4: 2022年度 | C4: 2023年度 | D4: 2024年度 | E4: 2025年度 | F4: 2026年1-6月 | G4: 口径/版本 | H4: 备注
A5: 营业收入 | B5: 12300 | C5: 31826.88 | D5: 39276.6 | E5: 169926.93 | F5: 115200 | G5: 注册稿为主 | H5: 2022约（主营12,100约）；2024由2025年+332.64%倒算⚠️（申报稿审计值39,237.06）；2026H1约（披露11.52亿，+48.54%）
A6: 归母净利润 | B6: -2210.05 | C6: -1114.51 | D6: 9547.47 | E6: 27821.05 | F6: 27400 | G6: 注册稿为主 | H6: 2024申报稿9,450.18；2026H1约（披露2.74亿；上年同期-3,202.45）
A7: 扣非归母净利润 | B7: -807 | C7: -1801.91 | D7: 7847.65 | E7: 59075.28 | F7: 24400 | G7: 注册稿为主 | H7: 2022约；2024申报稿约7,750；2026H1约（披露2.44亿，-19.34%）
A8: 主营业务毛利率 | B8: 0.4418 | C8: 0.4422 | D8: 0.5674 | E8: 0.6013 | F8: 0.5601 | G8: 注册稿为主 | H8: 2022/2024申报稿44.18%/56.41%；2025申报稿经审阅60.27%；2026H1为综合毛利率⚠️单一来源
A9: 研发费用 | B9: 2998.48 | C9: 4995.18 | D9: 7001.7 | E9: 14500 | F9: 13600 | G9: 申报稿精确值+披露约数 | H9: 2025约（披露1.45亿，+107%）；2026H1约（披露1.36亿，同比+8,203.74）
A10: 研发费用率 | B10: 0.2439 | C10: 0.3139 | D10: 0.1784 | E10: 0.0853 | F10: 0.118 | G10: 披露值 | H10: 2026H1约11.8%为倒算⚠️
A11: 经营活动现金流净额 | B11: -3019.73 | C11: 494.25 | D11: 19200 | E11: 67000 | F11: 未披露 | G11: 申报稿/上会稿 | H11: 2022/2023⚠️单一来源；2024约（披露1.92亿）✅；2025约（披露6.70亿，+248.24%）✅；2026Q1为3,439.96⚠️
A13: 补充数据（申报稿/上会稿/上市公告书口径，单位：万元）
A14: 指标 | B14: 数值 | C14: 同比/对照 | D14: 备注
A15: 2025年1-9月营业收入（申报稿） | B15: 116700 | D15: 约
A16: 2025年1-9月归母净利润（申报稿） | B16: 10500 | D16: 约
A17: 2025年1-9月扣非归母净利润（申报稿） | B17: 43100 | D17: 约
A18: 2025年1-9月经营现金流净额（申报稿） | B18: 42800 | D18: 约✅多源
A19: 2026年1-3月营业收入（经审阅） | B19: 42284.05 | C19: +68.49% | D19: ✅多源
A20: 2026年1-3月扣非归母净利润（经审阅） | B20: 4025.36 | C20: -52.55%（上年同期8,483.65） | D20: ✅多源
A21: 2025年一次性股份支付费用 | B21: 34906.55 | D21: 全额计入管理费用且列为非经常性损益✅
A22: 2025年1-6月归母净利润（回溯） | B22: -3202.45 | D22: 上市公告书转述✅
A23: 2026年1-3月经营现金流净额 | B23: 3439.96 | C23: -85.65% | D23: ⚠️单一来源（精确）
A24: 注：2025年非经常性损益约-31,254（=归母27,821.05-扣非59,075.28，倒算），主因一次性股份支付34,906.55。主营业务收入同比增速（申报稿）：2023年+29.95%、2024年+145.83%、2025年+335.31%；注册稿营收口径2025年+332.64%。
A26: 数据块B：分产品收入（注册稿，✅双源；单位：万元）
A27: 产品 | B27: 2023收入 | C27: 2023占比 | D27: 2024收入 | E27: 2024占比 | F27: 2025收入 | G27: 2025占比 | H27: 备注
A28: 四足机器人 | B28: 11900 | C28: 0.7578 | D28: 23100 | E28: 0.5947 | F28: 69800 | G28: 0.4162 | H28: 约数（披露1.19亿/2.31亿/6.98亿）
A29: 人形机器人 | B29: 296.71 | C29: 0.0188 | D29: 10700 | E29: 0.2768 | F29: 86800 | G29: 0.5178 | H29: 2023精确；2024/2025约（披露1.07亿/8.68亿）
A30: 组件及其他 | B30: 3500 | C30: 0.223 | D30: 5000 | E30: 0.129 | F30: 11100 | G30: 0.066 | H30: ⚠️倒算（约）
A31: 主营业务收入（合计） | B31: 15700 | C31: 1 | D31: 38800 | E31: 1 | F31: 167700 | G31: 1 | H31: ⚠️倒算（约）
A32: 9M2025人形机器人收入（申报稿） | B32: 59500 | C32: 0.5153 | H32: ✅多源
A33: 9M2025四足机器人收入（申报稿） | B33: 48800 | C33: 0.4225 | H33: ✅多源
A34: 9M2025组件及其他收入（申报稿） | B34: 6700 | C34: 0.058 | H34: 约5.8%
A36: 数据块C：分地区收入（申报稿，主营业务收入；单位：万元）
A37: 报告期 | B37: 境外收入 | C37: 境外占比 | D37: 境内收入 | E37: 境内占比 | F37: 备注
A38: 2022年度 | B38: 6935.28 | C38: 0.5721 | F38: ✅
A39: 2023年度 | B39: 8764.24 | C39: 0.5563 | F39: ✅
A40: 2024年度 | B40: 21600 | C40: 0.557 | F40: 约✅
A41: 2025年1-9月 | B41: 45300 | C41: 0.392 | D41: 70200 | E41: 0.608 | F41: 境外+179.88%、境内+445.69%✅
A42: 2025全年 | B42: ⚠️一说73,200（43.65%） | F42: 与"同比+109.91%"自相矛盾，不纳入计算，列待核验
A43: 补充：2025年美国市场收入占比 | B43: 0.133 | F43: ⚠️单一来源（称出自招股意向书风险章节）待核验
A44: 补充：2025年前五大客户合计 | B44: 20500 | C44: 0.1209 | F44: ⚠️单一来源（京东4,887等）
...

Sheet 原始数据_IPO与股东
A1: 原始数据_IPO与股东（数据块G：上市公告书/发行公告✅）
A3: 发行要素表
A4: 项目 | B4: 数值 | C4: 单位 | D4: 备注
A5: 证券代码/简称 | B5: 688836 / 宇树科技（-W表决权差异） | D5: 网上申购代码787836
A6: 发行价 | B6: 150.8 | C6: 元/股
A7: 新发股数 | B7: 4044.6434 | C7: 万股 | D7: 全部新股，占发行后总股本10.00%
A8: 发行后总股本 | B8: 40446.434 | C8: 万股 | D8: 发行前36,401.7906万股
A9: 募资总额 | B9: 609932.22 | C9: 万元 | D9: 约60.99亿元
A10: 募资净额 | B10: 591714.92 | C10: 万元 | D10: 约59.17亿元
A11: 发行费用 | B11: 18217.31 | C11: 万元 | D11: 承销保荐费14,499.32万元
A12: 计划募资 | B12: 420171.12 | C12: 万元 | D12: 42.02亿元
A13: 超募金额 | B13: 171500 | C13: 万元 | D13: 约17.15亿元（约）
A14: 发行市盈率 | B14: 219.23 | C14: 倍 | D14: ＝发行市值609.93亿/2025年归母净利润2.7821亿（扣非前后孰低摊薄）
A15: 行业市盈率（C34通用设备） | B15: 38.56 | C15: 倍
A16: 静态市销率 | B16: 35.89 | C16: 倍 | D16: ＝609.93亿/16.9927亿
A17: 网上中签率 | B17: 0.0001809759 | D17: 科创板历史新低
A18: 上市初无限售流通股 | B18: 3008.772 | C18: 万股 | D18: 仅占发行后总股本7.44%
A19: 发行时市值 | B19: 609.93 | C19: 亿元 | D19: 满足"市值不低于100亿元"上市标准
A21: IPO时间线
A22: 节点 | B22: 日期 | C22: 说明
A23: 辅导备案 | B23: 2025-07-08 | C23: 中信证券提交辅导备案
A24: 上交所受理 | B24: 2026-03-20 | C24: 科创板"预先审阅"第2单；保荐中信证券、审计容诚、律师北京德恒
A25: 过会 | B25: 2026-06-01 | C25: 受理到过会73天，创2026年科创板最快纪录
A26: 注册生效 | B26: 2026-07-02 | C26: 证监许可〔2026〕1612号；受理起104天
A27: 招股意向书 | B27: 2026-07-31
A28: 网上/网下申购 | B28: 2026-08-10 | C28: 网上有效申购978.46万户（科创板历史新高）
A29: 上市日 | B29: 2026-08-19 | C29: 上交所科创板挂牌
A31: 股东结构表（发行前）
A32: 股东 | B32: 发行前持股 | C32: 备注
A33: 王兴兴（直接+上海宇翼） | B33: 0.333583 | C33: 直接23.8216%+上海宇翼9.5367%；发行后直接21.4395%、合计控制表决权65.31%；锁定36个月
A34: 美团系 | B34: 0.096488 | C34: 第一大外部机构股东（汉海信息7.61%+成都龙珠1.02%+Galaxy Z 1.02%）
A35: 红杉中国 | B35: 0.071149 | C35: 2019年1,500万入场（估值约1.5亿）
A36: 经纬创投 | B36: 0.054528
A37: 顺为资本 | B37: 0.044245 | C37: 2021年A轮独家投资
A38: 中信系 | B38: 0.0449 | C38: 金石成长4.15%+中证投资0.34%
A39: 北京机器人产业发展投资基金 | B39: 0.0383
A40: 源码资本 | B40: 0.026 | C40: 2024年B2轮起连续加注
A41: 锁定期：控股股东/实控人王兴兴36个月；战略配售：DeepSeek 36个月（外部战配最长）/社保基金等12个月；中信证券投资跟投24个月；网下获配10%限售6个月。
A43: 募投项目表（合计420,171.12万元≈42.02亿元）
A44: 项目 | B44: 拟投入（万元） | C44: 备注
...

Sheet 原始数据_经营
A1: 原始数据_经营（数据块H+市占率/下游应用/定价/大事记；官方/表态/机构分级标注）
A3: 产品定价表（官方）
A4: 型号/产品 | B4: 定价 | C4: 备注
A5: Go2（四足） | B5: 9,997元起 | C5: 海外$1,600起
A6: G1（人形） | B6: 发布9.9万起→2026年降至8.5万 | C6: 海外$13,500起；截至2026-05累计下线约11,000台
A7: R1（人形） | B7: 3.99万起→2026-06-24降至2.99万起 | C7: 消费级入门
A8: H1（人形） | B8: 约65万/台 | C8: 首款通用人形
A10: 产能
A11: 指标 | B11: 数值（台） | C11: 备注
A12: 纯双足人形累计下线（截至2026-07） | B12: 18000 | C12: 约（官方）
A13: G1单款累计下线（截至2026-05） | B13: 11000 | C13: 约（官方）
A15: 市占率表
A16: 指标 | B16: 数值 | C16: 口径/来源 | D16: 备注
A17: 四足全球销量份额 | B17: 60%–70% | C17: 王兴兴2025-07-15国新办表态✅ | D17: 管理层口径
A18: 四足2023年全球销量份额 | B18: 0.6975 | C18: GGII（机构数据）
A19: 人形2025年出货份额 | B19: 0.324 | C19: 赛迪顾问，被注册批复报道引用✅ | D19: 出货超5,500台全球第一；第三方口径差异：Omdia 4,200台/Counterpoint 26.4%（列待核验）
A21: 下游应用结构表（2025年1-9月，申报稿✅）
A22: 产品 | B22: 科研教育 | C22: 商业消费 | D22: 行业应用 | E22: 备注
A23: 人形机器人 | B23: 0.736 | C23: 0.1739 | D23: 0.0901 | E23: 科研教育43,800万；真实生产场景（智能制造/智能巡检等）仅1,570万、占主营2.64%⚠️单一来源
A24: 四足机器人 | B24: 0.3158 | C24: 0.423 | D24: 0.2612 | E24: 商业消费首超科研教育成第一大场景
A26: 2026大事记表
A27: 时间 | B27: 事件
A28: 2026-02 | B28: 马年春晚《武BOT》：G1+H2全球首次全自主人形机器人集群武术表演
A29: 2026-03-17 | B29: 英伟达GTC合作H2参考平台（王兴兴具身智能主论坛演讲）
A30: 2026年初 | B30: 自研工业级具身大模型UnifoLM-X1-0在自有工厂完成试点部署测试
A31: 2026-06-24 | B31: R1降价：3.99万→2.99万元起并现货开售
A32: 2026-07 | B32: As2-W轮足复合机器人发布（工业巡检/户外勘探）
A33: 2026-07-28 | B33: 美国FCC禁令：禁止进口中国新型人形/四足机器人（即日生效，仅限新型号）
A34: 2026-08-17 | B34: 发布"超人"人形机器人原型机（跳高2米、12.66m/s）
A35: 2026-08-19 | B35: 科创板上市（688836）
A36: 2026-08下旬 | B36: 全资子公司天津宇天科技注册落地（港口/石油石化/制造场景）
A38: 行业预测表（🔮第三方预测，严禁写成事实）
A39: 机构 | B39: 预测内容
A40: GGII（高工机器人） | B40: 预测2030年全球人形机器人销量60.57万台/市场规模150亿美元（第三方预测）
A41: 摩根士丹利 | B41: 预测2030年全球人形机器人销量900万台（第三方预测）
A42: SAG（Smart Analytics Global） | B42: 预测2026年全球人形机器人出货约6万台（第三方预测）

Sheet 核心计算
A1: 核心计算（全部为Excel公式跨表引用原始数据sheet，未硬编码计算结果）
A3: 1. 营业收入同比增速（计算值 vs 披露值）
A4: 指标 | B4: 2023 | C4: 2024 | D4: 2025 | E4: 备注
A5: 营收同比增速（公式计算） | B5: =原始数据_财务!C5/原始数据_财务!B5-1 -> 1.5875512 | C5: =原始数据_财务!D5/原始数据_财务!C5-1 -> 0.23407007 | D5: =原始数据_财务!E5/原始数据_财务!D5-1 -> 3.3264165 | E5: 营业收入口径；2022/2024营收为约数，故与披露值略有差异
A6: 披露值对照（主营业务收入口径） | B6: 0.2995 | C6: 1.4583 | D6: 3.3264 | E6: 申报稿主营口径+29.95%/+145.83%/+335.31%；注册稿营收口径2025年+332.64%
A8: 2. 归母净利率、扣非净利率（2023–2025）
A9: 指标 | B9: 2023 | C9: 2024 | D9: 2025 | E9: 备注
A10: 归母净利率 | B10: =原始数据_财务!C6/原始数据_财务!C5 -> -0.035017884 | C10: =原始数据_财务!D6/原始数据_财务!D5 -> 0.2430829 | D10: =原始数据_财务!E6/原始数据_财务!E5 -> 0.16372361
A11: 扣非净利率 | B11: =原始数据_财务!C7/原始数据_财务!C5 -> -0.05661598 | C11: =原始数据_财务!D7/原始数据_财务!D5 -> 0.19980472 | D11: =原始数据_财务!E7/原始数据_财务!E5 -> 0.34765108 | E11: 2025年扣非净利率约34.8%
A13: 3. 研发费用率复算（2022–2025）
A14: 指标 | B14: 2022 | C14: 2023 | D14: 2024 | E14: 2025 | F14: 备注
A15: 研发费用率（复算=研发费用/营业收入） | B15: =原始数据_财务!B9/原始数据_财务!B5 -> 0.24377886 | C15: =原始数据_财务!C9/原始数据_财务!C5 -> 0.15694847 | D15: =原始数据_财务!D9/原始数据_财务!D5 -> 0.17826645 | E15: =原始数据_财务!E9/原始数据_财务!E5 -> 0.085330795 | F15: 2022/2024营收为约数，复算与披露基本一致
A16: 披露值对照 | B16: 0.2439 | C16: 0.3139 | D16: 0.1784 | E16: 0.0853
A18: 4. 2023–2025营收CAGR
A19: 指标 | B19: 数值 | C19: 披露对照 | D19: 备注
A20: 营收CAGR（2023–2025） | B20: =POWER(原始数据_财务!E5/原始数据_财务!C5,1/2)-1 -> 1.3106495 | C20: 2.2678 | D20: 对照披露226.78%
A22: 5. 分产品收入占比复算（2023–2025，占主营业务收入）
A23: 产品 | B23: 2023计算 | C23: 2023披露 | D23: 2024计算 | E23: 2024披露 | F23: 2025计算 | G23: 2025披露
A24: 四足机器人 | B24: =原始数据_财务!B28/原始数据_财务!B31 -> 0.75796178 | C24: =原始数据_财务!C28 -> 0.7578 | D24: =原始数据_财务!D28/原始数据_财务!D31 -> 0.59536082 | E24: =原始数据_财务!E28 -> 0.5947 | F24: =原始数据_财务!F28/原始数据_财务!F31 -> 0.41621944 | G24: =原始数据_财务!G28 -> 0.4162
A25: 人形机器人 | B25: =原始数据_财务!B29/原始数据_财务!B31 -> 0.018898726 | C25: =原始数据_财务!C29 -> 0.0188 | D25: =原始数据_财务!D29/原始数据_财务!D31 -> 0.2757732 | E25: =原始数据_财务!E29 -> 0.2768 | F25: =原始数据_财务!F29/原始数据_财务!F31 -> 0.51759094 | G25: =原始数据_财务!G29 -> 0.5178
A26: 组件及其他 | B26: =原始数据_财务!B30/原始数据_财务!B31 -> 0.22292994 | C26: =原始数据_财务!C30 -> 0.223 | D26: =原始数据_财务!D30/原始数据_财务!D31 -> 0.12886598 | E26: =原始数据_财务!E30 -> 0.129 | F26: =原始数据_财务!F30/原始数据_财务!F31 -> 0.066189624 | G26: =原始数据_财务!G30 -> 0.066
A27: 合计（复算校验） | B27: =SUM(原始数据_财务!B28:'原始数据_财务'!B30)/原始数据_财务!B31 -> 0.99979045 | C27: 1 | D27: =SUM(原始数据_财务!D28:'原始数据_财务'!D30)/原始数据_财务!D31 -> 1 | E27: 1 | F27: =SUM(原始数据_财务!F28:'原始数据_财务'!F30)/原始数据_财务!F31 -> 1 | G27: 1
A28: 注：主营业务收入为倒算约数（⚠️），故计算占比与披露占比存在小幅差异；组件及其他占比本身为倒算值。
A30: 6. 人形机器人收入=销量×单价交叉验证（9M2025）
A31: 指标 | B31: 数值（万元） | C31: 披露对照（万元） | D31: 备注
A32: 9M2025人形销量×平均单价 | B32: =原始数据_财务!E49*原始数据_财务!E50 -> 59514.76 | C32: 59500 | D32: ≈59,515万，与披露人形收入59,500万自洽✅（差异为单价四舍五入）
A34: 7. 经营现金流净额/扣非归母净利润（2024、2025）
A35: 指标 | B35: 2024 | C35: 2025 | D35: 备注
A36: 经营现金流/扣非净利润 | B36: =原始数据_财务!D11/原始数据_财务!D7 -> 2.4465923 | C36: =原始数据_财务!E11/原始数据_财务!E7 -> 1.1341461 | D36: >1说明利润含金量高；现金流为约数（披露1.92亿/6.70亿）
A38: 8. 非经常性损益（2025）及股份支付占比
A39: 指标 | B39: 数值 | C39: 备注
A40: 2025年非经常性损益（=归母-扣非，万元） | B40: =原始数据_财务!E6-原始数据_财务!E7 -> -31254.23 | C40: 约-31,254万（倒算）
A41: 股份支付/（扣非-归母） | B41: =原始数据_财务!B21/(原始数据_财务!E7-原始数据_财务!E6) -> 1.1168584 | C41: 一次性股份支付34,906.55万计入管理费用✅，是归母与扣非差异主因
A43: 9. 估值指标：各时点市值对应PE（2025归母）/PS（2025营收）——以二级市场数据计算
A44: 时点 | B44: 市值（亿元，公式引用） | C44: 市值（万元） | D44: PE（2025归母） | E44: PS（2025营收） | F44: 备注
A45: 发行时 | B45: =原始数据_IPO与股东!B19 -> 609.93 | C45: =B45*10000 -> 6099300 | D45: =C45/原始数据_财务!E6 -> 219.23328 | E45: =C45/原始数据_财务!E5 -> 35.893663 | F45: 发行价150.80元×发行后总股本
A46: 首日收盘（2026-08-19） | B46: =原始数据_IPO与股东!C53 -> 3417.72 | C46: =B46*10000 -> 34177200 | D46: =C46/原始数据_财务!E6 -> 1228.4655 | E46: =C46/原始数据_财务!E5 -> 201.1288 | F46: 收盘845元；二级市场数据
A47: 2026-08-31（补充） | B47: =原始数据_IPO与股东!C57 -> 2285 | C47: =B47*10000 -> 22850000 | D47: =C47/原始数据_财务!E6 -> 821.32055 | E47: =C47/原始数据_财务!E5 -> 134.46956 | F47: 收564.90元；二级市场数据
A48: 注：发行PE按归母口径复算约219倍（与披露219.23倍一致，披露口径为扣非前后孰低摊薄）；首日收盘PE约1,228倍；8月底PE约821倍。
A50: 10. 人均创收（2025）
...

Sheet 趋势图表
A1: 趋势图表（顶部为图表数据区，均为公式引用原始数据sheet；下方为7个原生Excel图表）
A3: 数据区1：营业收入与归母净利润（2022–2025，万元）
A4: 年度 | B4: 营业收入（万元） | C4: 归母净利润（万元）
A5: 2022 | B5: =原始数据_财务!B5 -> 12300 | C5: =原始数据_财务!B6 -> -2210.05
A6: 2023 | B6: =原始数据_财务!C5 -> 31826.88 | C6: =原始数据_财务!C6 -> -1114.51
A7: 2024 | B7: =原始数据_财务!D5 -> 39276.6 | C7: =原始数据_财务!D6 -> 9547.47
A8: 2025 | B8: =原始数据_财务!E5 -> 169926.93 | C8: =原始数据_财务!E6 -> 27821.05
A10: 数据区2：主营业务毛利率与研发费用率（2022–2025）
A11: 年度 | B11: 主营业务毛利率 | C11: 研发费用率
A12: 2022 | B12: =原始数据_财务!B8 -> 0.4418 | C12: =原始数据_财务!B10 -> 0.2439
A13: 2023 | B13: =原始数据_财务!C8 -> 0.4422 | C13: =原始数据_财务!C10 -> 0.3139
A14: 2024 | B14: =原始数据_财务!D8 -> 0.5674 | C14: =原始数据_财务!D10 -> 0.1784
A15: 2025 | B15: =原始数据_财务!E8 -> 0.6013 | C15: =原始数据_财务!E10 -> 0.0853
A17: 数据区3：分产品收入（2023–2025，万元）
A18: 年度 | B18: 四足机器人（万元） | C18: 人形机器人（万元） | D18: 组件及其他（万元）
A19: 2023 | B19: =原始数据_财务!B28 -> 11900 | C19: =原始数据_财务!B29 -> 296.71 | D19: =原始数据_财务!B30 -> 3500
A20: 2024 | B20: =原始数据_财务!D28 -> 23100 | C20: =原始数据_财务!D29 -> 10700 | D20: =原始数据_财务!D30 -> 5000
A21: 2025 | B21: =原始数据_财务!F28 -> 69800 | C21: =原始数据_财务!F29 -> 86800 | D21: =原始数据_财务!F30 -> 11100
A23: 数据区4：人形机器人销量与平均单价（2023/2024/2025年1-9月）
A24: 期间 | B24: 人形销量（台） | C24: 人形平均单价（万元/台）
A25: 2023 | B25: =原始数据_财务!C49 -> 5 | C25: =原始数据_财务!C50 -> 59.34
A26: 2024 | B26: =原始数据_财务!D49 -> 410 | C26: =原始数据_财务!D50 -> 26.07
A27: 2025年1-9月 | B27: =原始数据_财务!E49 -> 3551 | C27: =原始数据_财务!E50 -> 16.76
A29: 数据区5：境外收入与境外占比（2022/2023/2024/2025年1-9月）
A30: 期间 | B30: 境外收入（万元） | C30: 境外占比
A31: 2022 | B31: =原始数据_财务!B38 -> 6935.28 | C31: =原始数据_财务!C38 -> 0.5721
A32: 2023 | B32: =原始数据_财务!B39 -> 8764.24 | C32: =原始数据_财务!C39 -> 0.5563
A33: 2024 | B33: =原始数据_财务!B40 -> 21600 | C33: =原始数据_财务!C40 -> 0.557
A34: 2025年1-9月 | B34: =原始数据_财务!B41 -> 45300 | C34: =原始数据_财务!C41 -> 0.392
A36: 数据区6：经营活动现金流净额（2022–2025，万元）
A37: 年度 | B37: 经营活动现金流净额（万元）
A38: 2022 | B38: =原始数据_财务!B11 -> -3019.73
A39: 2023 | B39: =原始数据_财务!C11 -> 494.25
A40: 2024 | B40: =原始数据_财务!D11 -> 19200
A41: 2025 | B41: =原始数据_财务!E11 -> 67000
A43: 数据区7：市值轨迹（亿元，二级市场数据）
A44: 时点 | B44: 市值（亿元）
A45: 发行时 | B45: =原始数据_IPO与股东!B19 -> 609.93
A46: 首日收盘(08-19) | B46: =原始数据_IPO与股东!C53 -> 3417.72
A47: 2026-08-20 | B47: =原始数据_IPO与股东!B54*原始数据_IPO与股东!B8/10000 -> 2778.67
...

Sheet 分析结论
A1: 分析结论（事实与数字以原始数据sheet为准；🔮=第三方预测，⚠️=待核验）
A3: 一、成长性
A4: · 营业收入由2022年约1.23亿元增至2025年16.99亿元（169,926.93万元），2023–2025年CAGR约226.8%，2025年同比+332.64%。
A5: · 2026年上半年营收11.52亿元（+48.54%），增速较2025年回落但仍处高增长区间。
A6: · 核心驱动：人形机器人放量（收入由2023年296.71万元增至2025年约8.68亿元）叠加四足机器人稳健增长。
A7: 二、业务结构切换
A8: · 人形机器人收入占比由2023年1.88%升至2025年51.78%，成为第一大产品。
A9: · 四足机器人占比降至41.62%，但绝对额仍增至约6.98亿元（全球销量份额60%–70%）。
A10: · 人形平均单价由59.34万元/台降至16.76万元/台，以价换量特征明显。
A11: 三、盈利能力
A12: · 2024年实现扭亏（归母净利润9,547.47万元）。
A13: · 主营业务毛利率由2023年44.22%持续上行至2025年60.13%（规模效应+高毛利人形占比提升；人形毛利率约62.9%⚠️期间口径待核验）。
... A42: · 机构观点与行业规模数据为第三方预测（🔮），严禁当作事实引用；本底稿仅为数据整理分析，不构成投资建议。

Sheet 待核验事项
A1: 待核验事项（合并三份调研清单去重；⚠️=单一来源/倒算/约数）
A2: 序号 | B2: 事项 | C2: 当前采用值 | D2: 问题说明 | E2: 建议核验渠道
A3: 1 | B3: 2024年营业收入（注册稿）精确值 | C3: 39,276.6万元（倒算） | D3: 媒体仅报"3.93亿"，按2025年+332.64%反推；申报稿审计值39,237.06万元，两版差约40万元 | E3: 招股说明书注册稿/正式稿原文（上交所公告）
A4: 2 | B4: 2025年末资产负债数据 | C4: 总资产321,500/总负债60,200/所有者权益261,300万元 | D4: 仅长江商报单一来源；归母所有者权益未见单独披露 | E4: 招股说明书正式稿、上市后定期报告
A5: 3 | B5: 2025年全年分地区收入 | C5: 未纳入计算（一说境外73,200万元/43.65%） | D5: 该说与"同比+109.91%"自相矛盾；媒体均止步于9M2025（境外4.53亿/境内7.02亿） | E5: 招股说明书正式稿分地区披露、年报
A6: 4 | B6: 2025年美国市场收入占比 | C6: 13.3%（仅备注引用） | D6: 单一来源（称出自招股意向书风险章节） | E6: 招股意向书风险章节原文
A7: 5 | B7: 2026H1毛利率/净利率 | C7: 综合毛利率56.01%（净利率23.78%未采用） | D7: 单一来源（个人专栏），与归母2.74亿/营收11.52亿自洽但待证实 | E7: 2026年半年报（截至2026-08-30未披露）
A8: 6 | B8: 2026H1费用明细 | C8: 研发费用13,600万元（约，+152%）；销售费用+约250% | D8: 源自媒体中报盘点；费用明细待正式半年报确认 | E8: 2026年半年报、上市公告书补充
A9: 7 | B9: 2025年末员工人数 | C9: 516人（研发184/销售154/生产123） | D9: 仅猎聘单一来源；与王兴兴"约1000人"（2025-06达沃斯）口径冲突 | E9: 定期报告"在职员工总数"披露
A10: 8 | B10: 人形机器人2025全年销量 | C10: 官方出货量口径：超5,500台、全球第一 | D10: 芝能科技称5,215台（待核验）；销量≠出货量口径差异 | E10: 招股说明书/年报销量披露
A11: 9 | B11: 四足机器人2025全年销量 | C11: 约25,500台（约） | D11: 单一来源（产业通）；官方口径为累计超3.3万台 | E11: 年报/官方披露
A12: 10 | B12: 2025年人形机器人毛利率期间口径 | C12: 约62.9% | D12: 全年还是前三季度口径不明；2025全年四足毛利率未见披露 | E12: 招股说明书分产品毛利披露
A13: 11 | B13: 2025H1扣非归母净利润 | C13: 约30,260万元（倒算） | D13: 由2026H1同比-19.34%反推，未见直接披露 | E13: 上市公告书/2026年半年报
A14: 12 | B14: 2022年扣非归母净利润 | C14: -807万元（约） | D14: 申报稿口径，不在注册稿报告期内；非精确到元 | E14: 申报稿审计报告
... A21: 19 | B21: 2026年正式半年报 | C21: 未披露（2026H1数据以上市公告书为准） | D21: 经上交所公告列表核实，截至2026-08-30未披露半年报；后续需跟踪三季报/年报 | E21: 上交所688836公告列表持续跟踪
